 
 -------------- celery@andrei-golubenko-macbook.local v5.5.3 (immunity)
--- ***** ----- 
-- ******* ---- macOS-26.0-arm64-arm-64bit-Mach-O 2025-10-14 00:44:46
- *** --- * --- 
- ** ---------- [config]
- ** ---------- .> app:         hrhelper:0x10ab6bb60
- ** ---------- .> transport:   redis://127.0.0.1:6379/0
- ** ---------- .> results:     redis://127.0.0.1:6379/0
- *** --- * --- .> concurrency: 1 (prefork)
-- ******* ---- .> task events: OFF (enable -E to monitor tasks in this worker)
--- ***** ----- 
 -------------- [queues]
                .> celery           exchange=celery(direct) key=celery
                

[tasks]
  . apps.clickup_int.tasks.bulk_import_clickup_tasks
  . apps.clickup_int.tasks.import_single_task
  . apps.clickup_int.tasks.retry_failed_tasks
  . apps.finance.tasks.analyze_hh_vacancies_automatic
  . apps.finance.tasks.analyze_hh_vacancies_batch
  . apps.finance.tasks.analyze_hh_vacancy_with_ai
  . apps.finance.tasks.cleanup_old_benchmarks
  . apps.finance.tasks.fetch_hh_vacancies_task
  . apps.finance.tasks.generate_benchmark_statistics
  . apps.finance.tasks.process_hh_queue_with_limit
  . apps.finance.tasks.save_hh_analysis_result
  . apps.finance.tasks.update_currency_rates
  . apps.huntflow.tasks.check_huntflow_token_health
  . apps.huntflow.tasks.refresh_huntflow_tokens
  . apps.notion_int.tasks.auto_sync_notion_pages
  . apps.notion_int.tasks.bulk_import_notion_pages
  . apps.notion_int.tasks.retry_failed_pages
  . config.celery.debug_task
  . config.celery.save_hh_analysis_result
  . config.celery.update_currency_rates

[2025-10-14 00:44:46,145: INFO/MainProcess] Connected to redis://127.0.0.1:6379/0
[2025-10-14 00:44:46,149: INFO/MainProcess] mingle: searching for neighbors
[2025-10-14 00:44:47,170: INFO/MainProcess] mingle: all alone
[2025-10-14 00:44:47,183: INFO/MainProcess] celery@andrei-golubenko-macbook.local ready.
[2025-10-14 00:45:03,361: INFO/MainProcess] Task apps.finance.tasks.process_hh_queue_with_limit[e2215940-0f18-4fef-9f22-ad04b88207c8] received
[2025-10-14 00:45:03,421: ERROR/ForkPoolWorker-1] Task apps.finance.tasks.process_hh_queue_with_limit[e2215940-0f18-4fef-9f22-ad04b88207c8] raised unexpected: NameError("name 'HHVacancyService' is not defined")
Traceback (most recent call last):
  File "/Users/agolubenko/hrhelper/fullstack/backend/venv/lib/python3.13/site-packages/celery/app/trace.py", line 453, in trace_task
    R = retval = fun(*args, **kwargs)
                 ~~~^^^^^^^^^^^^^^^^^
  File "/Users/agolubenko/hrhelper/fullstack/backend/venv/lib/python3.13/site-packages/celery/app/trace.py", line 736, in __protected_call__
    return self.run(*args, **kwargs)
           ~~~~~~~~^^^^^^^^^^^^^^^^^
  File "/Users/agolubenko/hrhelper/fullstack/backend/apps/finance/tasks.py", line 617, in process_hh_queue_with_limit
    hh_service = HHVacancyService()
                 ^^^^^^^^^^^^^^^^
NameError: name 'HHVacancyService' is not defined
[2025-10-14 00:45:49,238: INFO/MainProcess] Task apps.finance.tasks.process_hh_queue_with_limit[85edb3c6-a652-44f7-b9b2-d2a910bdbccb] received
[2025-10-14 00:45:49,242: INFO/MainProcess] Task apps.finance.tasks.process_hh_queue_with_limit[686545cb-7ae8-4fda-87df-91a171e819b7] received
[2025-10-14 00:45:49,277: ERROR/ForkPoolWorker-1] Task apps.finance.tasks.process_hh_queue_with_limit[85edb3c6-a652-44f7-b9b2-d2a910bdbccb] raised unexpected: NameError("name 'HHVacancyService' is not defined")
Traceback (most recent call last):
  File "/Users/agolubenko/hrhelper/fullstack/backend/venv/lib/python3.13/site-packages/celery/app/trace.py", line 453, in trace_task
    R = retval = fun(*args, **kwargs)
                 ~~~^^^^^^^^^^^^^^^^^
  File "/Users/agolubenko/hrhelper/fullstack/backend/venv/lib/python3.13/site-packages/celery/app/trace.py", line 736, in __protected_call__
    return self.run(*args, **kwargs)
           ~~~~~~~~^^^^^^^^^^^^^^^^^
  File "/Users/agolubenko/hrhelper/fullstack/backend/apps/finance/tasks.py", line 617, in process_hh_queue_with_limit
    hh_service = HHVacancyService()
                 ^^^^^^^^^^^^^^^^
NameError: name 'HHVacancyService' is not defined
[2025-10-14 00:45:49,287: ERROR/ForkPoolWorker-1] Task apps.finance.tasks.process_hh_queue_with_limit[686545cb-7ae8-4fda-87df-91a171e819b7] raised unexpected: NameError("name 'HHVacancyService' is not defined")
Traceback (most recent call last):
  File "/Users/agolubenko/hrhelper/fullstack/backend/venv/lib/python3.13/site-packages/celery/app/trace.py", line 453, in trace_task
    R = retval = fun(*args, **kwargs)
                 ~~~^^^^^^^^^^^^^^^^^
  File "/Users/agolubenko/hrhelper/fullstack/backend/venv/lib/python3.13/site-packages/celery/app/trace.py", line 736, in __protected_call__
    return self.run(*args, **kwargs)
           ~~~~~~~~^^^^^^^^^^^^^^^^^
  File "/Users/agolubenko/hrhelper/fullstack/backend/apps/finance/tasks.py", line 617, in process_hh_queue_with_limit
    hh_service = HHVacancyService()
                 ^^^^^^^^^^^^^^^^
NameError: name 'HHVacancyService' is not defined
[2025-10-14 00:52:00,057: INFO/MainProcess] Task apps.finance.tasks.process_hh_queue_with_limit[f1564655-d0c9-42c6-a714-4bc4c937b98e] received
[2025-10-14 00:52:00,248: ERROR/ForkPoolWorker-1] Task apps.finance.tasks.process_hh_queue_with_limit[f1564655-d0c9-42c6-a714-4bc4c937b98e] raised unexpected: NameError("name 'HHVacancyService' is not defined")
Traceback (most recent call last):
  File "/Users/agolubenko/hrhelper/fullstack/backend/venv/lib/python3.13/site-packages/celery/app/trace.py", line 453, in trace_task
    R = retval = fun(*args, **kwargs)
                 ~~~^^^^^^^^^^^^^^^^^
  File "/Users/agolubenko/hrhelper/fullstack/backend/venv/lib/python3.13/site-packages/celery/app/trace.py", line 736, in __protected_call__
    return self.run(*args, **kwargs)
           ~~~~~~~~^^^^^^^^^^^^^^^^^
  File "/Users/agolubenko/hrhelper/fullstack/backend/apps/finance/tasks.py", line 617, in process_hh_queue_with_limit
    hh_service = HHVacancyService()
                 ^^^^^^^^^^^^^^^^
NameError: name 'HHVacancyService' is not defined
[2025-10-14 00:52:45,911: INFO/MainProcess] Task apps.finance.tasks.process_hh_queue_with_limit[56bef790-f0c6-4b11-8431-84f74d73ff2a] received
[2025-10-14 00:52:45,915: INFO/MainProcess] Task apps.finance.tasks.process_hh_queue_with_limit[1c4b0b8d-f3b1-4d89-94ee-df71a0385c65] received
[2025-10-14 00:52:45,942: ERROR/ForkPoolWorker-1] Task apps.finance.tasks.process_hh_queue_with_limit[56bef790-f0c6-4b11-8431-84f74d73ff2a] raised unexpected: NameError("name 'HHVacancyService' is not defined")
Traceback (most recent call last):
  File "/Users/agolubenko/hrhelper/fullstack/backend/venv/lib/python3.13/site-packages/celery/app/trace.py", line 453, in trace_task
    R = retval = fun(*args, **kwargs)
                 ~~~^^^^^^^^^^^^^^^^^
  File "/Users/agolubenko/hrhelper/fullstack/backend/venv/lib/python3.13/site-packages/celery/app/trace.py", line 736, in __protected_call__
    return self.run(*args, **kwargs)
           ~~~~~~~~^^^^^^^^^^^^^^^^^
  File "/Users/agolubenko/hrhelper/fullstack/backend/apps/finance/tasks.py", line 617, in process_hh_queue_with_limit
    hh_service = HHVacancyService()
                 ^^^^^^^^^^^^^^^^
NameError: name 'HHVacancyService' is not defined
[2025-10-14 00:52:45,954: ERROR/ForkPoolWorker-1] Task apps.finance.tasks.process_hh_queue_with_limit[1c4b0b8d-f3b1-4d89-94ee-df71a0385c65] raised unexpected: NameError("name 'HHVacancyService' is not defined")
Traceback (most recent call last):
  File "/Users/agolubenko/hrhelper/fullstack/backend/venv/lib/python3.13/site-packages/celery/app/trace.py", line 453, in trace_task
    R = retval = fun(*args, **kwargs)
                 ~~~^^^^^^^^^^^^^^^^^
  File "/Users/agolubenko/hrhelper/fullstack/backend/venv/lib/python3.13/site-packages/celery/app/trace.py", line 736, in __protected_call__
    return self.run(*args, **kwargs)
           ~~~~~~~~^^^^^^^^^^^^^^^^^
  File "/Users/agolubenko/hrhelper/fullstack/backend/apps/finance/tasks.py", line 617, in process_hh_queue_with_limit
    hh_service = HHVacancyService()
                 ^^^^^^^^^^^^^^^^
NameError: name 'HHVacancyService' is not defined
[2025-10-14 00:57:00,034: INFO/MainProcess] Task apps.finance.tasks.process_hh_queue_with_limit[f4a79194-74e0-4349-8716-607a0c7da6c2] received
[2025-10-14 00:57:00,100: ERROR/ForkPoolWorker-1] Task apps.finance.tasks.process_hh_queue_with_limit[f4a79194-74e0-4349-8716-607a0c7da6c2] raised unexpected: NameError("name 'HHVacancyService' is not defined")
Traceback (most recent call last):
  File "/Users/agolubenko/hrhelper/fullstack/backend/venv/lib/python3.13/site-packages/celery/app/trace.py", line 453, in trace_task
    R = retval = fun(*args, **kwargs)
                 ~~~^^^^^^^^^^^^^^^^^
  File "/Users/agolubenko/hrhelper/fullstack/backend/venv/lib/python3.13/site-packages/celery/app/trace.py", line 736, in __protected_call__
    return self.run(*args, **kwargs)
           ~~~~~~~~^^^^^^^^^^^^^^^^^
  File "/Users/agolubenko/hrhelper/fullstack/backend/apps/finance/tasks.py", line 617, in process_hh_queue_with_limit
    hh_service = HHVacancyService()
                 ^^^^^^^^^^^^^^^^
NameError: name 'HHVacancyService' is not defined
[2025-10-14 00:57:45,901: INFO/MainProcess] Task apps.finance.tasks.process_hh_queue_with_limit[70844b7c-e1b1-4278-a98b-fd325e0e06e4] received
[2025-10-14 00:57:45,920: INFO/MainProcess] Task apps.finance.tasks.process_hh_queue_with_limit[610a5a81-30e8-4f08-b6e1-9cd7cb82a074] received
[2025-10-14 00:57:45,950: ERROR/ForkPoolWorker-1] Task apps.finance.tasks.process_hh_queue_with_limit[70844b7c-e1b1-4278-a98b-fd325e0e06e4] raised unexpected: NameError("name 'HHVacancyService' is not defined")
Traceback (most recent call last):
  File "/Users/agolubenko/hrhelper/fullstack/backend/venv/lib/python3.13/site-packages/celery/app/trace.py", line 453, in trace_task
    R = retval = fun(*args, **kwargs)
                 ~~~^^^^^^^^^^^^^^^^^
  File "/Users/agolubenko/hrhelper/fullstack/backend/venv/lib/python3.13/site-packages/celery/app/trace.py", line 736, in __protected_call__
    return self.run(*args, **kwargs)
           ~~~~~~~~^^^^^^^^^^^^^^^^^
  File "/Users/agolubenko/hrhelper/fullstack/backend/apps/finance/tasks.py", line 617, in process_hh_queue_with_limit
    hh_service = HHVacancyService()
                 ^^^^^^^^^^^^^^^^
NameError: name 'HHVacancyService' is not defined
[2025-10-14 00:57:45,963: ERROR/ForkPoolWorker-1] Task apps.finance.tasks.process_hh_queue_with_limit[610a5a81-30e8-4f08-b6e1-9cd7cb82a074] raised unexpected: NameError("name 'HHVacancyService' is not defined")
Traceback (most recent call last):
  File "/Users/agolubenko/hrhelper/fullstack/backend/venv/lib/python3.13/site-packages/celery/app/trace.py", line 453, in trace_task
    R = retval = fun(*args, **kwargs)
                 ~~~^^^^^^^^^^^^^^^^^
  File "/Users/agolubenko/hrhelper/fullstack/backend/venv/lib/python3.13/site-packages/celery/app/trace.py", line 736, in __protected_call__
    return self.run(*args, **kwargs)
           ~~~~~~~~^^^^^^^^^^^^^^^^^
  File "/Users/agolubenko/hrhelper/fullstack/backend/apps/finance/tasks.py", line 617, in process_hh_queue_with_limit
    hh_service = HHVacancyService()
                 ^^^^^^^^^^^^^^^^
NameError: name 'HHVacancyService' is not defined
[2025-10-14 01:00:03,266: INFO/MainProcess] Task apps.finance.tasks.fetch_hh_vacancies_task[96c711ad-5cbe-4d7d-bf48-e8fe77788837] received
[2025-10-14 01:00:03,289: INFO/ForkPoolWorker-1] Task apps.finance.tasks.fetch_hh_vacancies_task[96c711ad-5cbe-4d7d-bf48-e8fe77788837] succeeded in 0.012493417016230524s: {'success': False, 'message': 'Задача временно отключена'}
